<?xml version="1.0" ?>
<sdf version="1.5">
<model name="falcon_cs_payload">
<static> 0 </static>

<link name="base_link">
	
<inertial>
	<pose>0.0	0.0	0.0	0.0	0.0	0.0	</pose>

<mass>0.9</mass>
<inertia>
	
<ixx>0.0049</ixx>
<iyy>0.0053</iyy>
<izz>0.0098</izz>
<ixy>5.5e-06</ixy>
<ixz>5.4e-06</ixz>
<iyz>2.1e-05</iyz>

</inertia>

</inertial>
<collision name="collision">
	<pose>0.0	0.0	0.0	0.0	0.0	0.0	</pose>

<geometry>
	
<box>
	
<size>0.2505 0.2505 0.09</size>

</box>

</geometry>
</collision>

<visual name="visual">
	<pose>0.0	0.0	0.0	0.0	0.0	-1.570796	</pose>

<geometry>
	
<mesh>
	
<uri>model://falcon_cs_payload/meshes/dega.dae</uri>
<scale>0.001 0.001 0.001</scale>

</mesh>

</geometry>
<material>
	
<script>
	
<uri>file://media/materials/scripts/gazebo.material</uri>
<name>Gazebo/Red</name>

</script>

</material>
</visual>

</link>

<!-- Groundtruth plugin -->
<plugin name="falcon_cs_payload_groundtruth_sim" filename="libgazebo_ros_p3d.so">
  <alwaysOn>true</alwaysOn>
  <updateRate>200.0</updateRate>
  <bodyName>base_link</bodyName>
  <topicName>/falcon_cs_payload/odometry/groundtruth</topicName>
  <gaussianNoise>0.0</gaussianNoise>
  <frameName>world</frameName>
  <xyzOffsets>0 0 0</xyzOffsets>
  <rpyOffsets>0 0 0</rpyOffsets>
</plugin>
        
<!-- Kite Quadrotor plugin-->
<plugin filename="libkite_quadrotor_plugin.so" name="falcon_cs_payload_kite_quadrotor_plugin">
  <publishRate>200.0</publishRate>
  <positionControlRate>100.0</positionControlRate>
  <attitudeControlRate>500.0</attitudeControlRate>
  <linkName>base_link</linkName>
  <namespace>falcon_cs_payload</namespace>
</plugin>
        
<link name = "link_0" >
<pose>0.05	0.0	0.0	0.0	0.0	0.0	</pose>

      <inertial>
        <pose>0 0 0 0 -0 0</pose>
        <mass>0.001</mass>
        <inertia>
          <ixx>0.0001</ixx>
          <ixy>0.0</ixy>
          <ixz>0.0</ixz>
          <iyy>0.0001</iyy>
          <iyz>0.0</iyz>
          <izz>0.0001</izz>
        </inertia>
      </inertial>
      <visual name='link_0_vis'>
        <pose>0 0 0 0.0 1.57079 0</pose>
        <geometry>
          <cylinder>
            <length>0.1</length>
            <radius>0.00125</radius>
          </cylinder>
        </geometry>
        <material>
          <shader type='pixel'/>
          <script>
            <uri>file://media/materials/scripts/gazebo.material</uri>
            <name>Gazebo/Yellow</name>
          </script>
        </material>
        <transparency>0</transparency>
        <cast_shadows>1</cast_shadows>
      </visual>
      <collision name='link_0_collision'>
        <laser_retro>0</laser_retro>
        <max_contacts>10</max_contacts>
        <pose>0  0 0 0.0 1.57079 0</pose>
        <geometry>
          <cylinder>
            <length>0.1</length>
            <radius>0.00125</radius>
          </cylinder>
        </geometry>
      </collision>
    </link>
<link name = "link_1" >
<pose>0.15000000000000002	0.0	0.0	0.0	0.0	0.0	</pose>

      <inertial>
        <pose>0 0 0 0 -0 0</pose>
        <mass>0.001</mass>
        <inertia>
          <ixx>0.0001</ixx>
          <ixy>0.0</ixy>
          <ixz>0.0</ixz>
          <iyy>0.0001</iyy>
          <iyz>0.0</iyz>
          <izz>0.0001</izz>
        </inertia>
      </inertial>
      <visual name='link_1_vis'>
        <pose>0 0 0 0.0 1.57079 0</pose>
        <geometry>
          <cylinder>
            <length>0.1</length>
            <radius>0.00125</radius>
          </cylinder>
        </geometry>
        <material>
          <shader type='pixel'/>
          <script>
            <uri>file://media/materials/scripts/gazebo.material</uri>
            <name>Gazebo/Yellow</name>
          </script>
        </material>
        <transparency>0</transparency>
        <cast_shadows>1</cast_shadows>
      </visual>
      <collision name='link_1_collision'>
        <laser_retro>0</laser_retro>
        <max_contacts>10</max_contacts>
        <pose>0  0 0 0.0 1.57079 0</pose>
        <geometry>
          <cylinder>
            <length>0.1</length>
            <radius>0.00125</radius>
          </cylinder>
        </geometry>
      </collision>
    </link>
<joint name='joint_0' type='universal'>
<parent>link_0</parent>
<child>link_1</child>
<pose>-0.05	0.0	0.0	0.0	0.0	0.0	</pose>
<axis>
        <xyz>0 1 0</xyz>
        <dynamics>
          <spring_reference>0</spring_reference>
          <spring_stiffness>0</spring_stiffness>
          <damping>0.0001</damping>
          <friction>0</friction>
        </dynamics>
      </axis>
      <axis2>
        <xyz>0 0 1</xyz>
        <dynamics>
          <spring_reference>0</spring_reference>
          <spring_stiffness>0</spring_stiffness>
          <damping>0.0001</damping>
          <friction>0</friction>
        </dynamics>
      </axis2>
      <physics>
        <ode>
          <limit>
            <cfm>0</cfm>
            <erp>0.2</erp>
          </limit>
          <suspension>
            <cfm>0</cfm>
            <erp>0.2</erp>
          </suspension>
        </ode>
      </physics>
    </joint>
<link name = "link_2" >
<pose>0.25	0.0	0.0	0.0	0.0	0.0	</pose>

      <inertial>
        <pose>0 0 0 0 -0 0</pose>
        <mass>0.001</mass>
        <inertia>
          <ixx>0.0001</ixx>
          <ixy>0.0</ixy>
          <ixz>0.0</ixz>
          <iyy>0.0001</iyy>
          <iyz>0.0</iyz>
          <izz>0.0001</izz>
        </inertia>
      </inertial>
      <visual name='link_2_vis'>
        <pose>0 0 0 0.0 1.57079 0</pose>
        <geometry>
          <cylinder>
            <length>0.1</length>
            <radius>0.00125</radius>
          </cylinder>
        </geometry>
        <material>
          <shader type='pixel'/>
          <script>
            <uri>file://media/materials/scripts/gazebo.material</uri>
            <name>Gazebo/Yellow</name>
          </script>
        </material>
        <transparency>0</transparency>
        <cast_shadows>1</cast_shadows>
      </visual>
      <collision name='link_2_collision'>
        <laser_retro>0</laser_retro>
        <max_contacts>10</max_contacts>
        <pose>0  0 0 0.0 1.57079 0</pose>
        <geometry>
          <cylinder>
            <length>0.1</length>
            <radius>0.00125</radius>
          </cylinder>
        </geometry>
      </collision>
    </link>
<joint name='joint_1' type='universal'>
<parent>link_1</parent>
<child>link_2</child>
<pose>-0.05	0.0	0.0	0.0	0.0	0.0	</pose>
<axis>
        <xyz>0 1 0</xyz>
        <dynamics>
          <spring_reference>0</spring_reference>
          <spring_stiffness>0</spring_stiffness>
          <damping>0.0001</damping>
          <friction>0</friction>
        </dynamics>
      </axis>
      <axis2>
        <xyz>0 0 1</xyz>
        <dynamics>
          <spring_reference>0</spring_reference>
          <spring_stiffness>0</spring_stiffness>
          <damping>0.0001</damping>
          <friction>0</friction>
        </dynamics>
      </axis2>
      <physics>
        <ode>
          <limit>
            <cfm>0</cfm>
            <erp>0.2</erp>
          </limit>
          <suspension>
            <cfm>0</cfm>
            <erp>0.2</erp>
          </suspension>
        </ode>
      </physics>
    </joint>
<link name = "link_3" >
<pose>0.35000000000000003	0.0	0.0	0.0	0.0	0.0	</pose>

      <inertial>
        <pose>0 0 0 0 -0 0</pose>
        <mass>0.001</mass>
        <inertia>
          <ixx>0.0001</ixx>
          <ixy>0.0</ixy>
          <ixz>0.0</ixz>
          <iyy>0.0001</iyy>
          <iyz>0.0</iyz>
          <izz>0.0001</izz>
        </inertia>
      </inertial>
      <visual name='link_3_vis'>
        <pose>0 0 0 0.0 1.57079 0</pose>
        <geometry>
          <cylinder>
            <length>0.1</length>
            <radius>0.00125</radius>
          </cylinder>
        </geometry>
        <material>
          <shader type='pixel'/>
          <script>
            <uri>file://media/materials/scripts/gazebo.material</uri>
            <name>Gazebo/Yellow</name>
          </script>
        </material>
        <transparency>0</transparency>
        <cast_shadows>1</cast_shadows>
      </visual>
      <collision name='link_3_collision'>
        <laser_retro>0</laser_retro>
        <max_contacts>10</max_contacts>
        <pose>0  0 0 0.0 1.57079 0</pose>
        <geometry>
          <cylinder>
            <length>0.1</length>
            <radius>0.00125</radius>
          </cylinder>
        </geometry>
      </collision>
    </link>
<joint name='joint_2' type='universal'>
<parent>link_2</parent>
<child>link_3</child>
<pose>-0.05	0.0	0.0	0.0	0.0	0.0	</pose>
<axis>
        <xyz>0 1 0</xyz>
        <dynamics>
          <spring_reference>0</spring_reference>
          <spring_stiffness>0</spring_stiffness>
          <damping>0.0001</damping>
          <friction>0</friction>
        </dynamics>
      </axis>
      <axis2>
        <xyz>0 0 1</xyz>
        <dynamics>
          <spring_reference>0</spring_reference>
          <spring_stiffness>0</spring_stiffness>
          <damping>0.0001</damping>
          <friction>0</friction>
        </dynamics>
      </axis2>
      <physics>
        <ode>
          <limit>
            <cfm>0</cfm>
            <erp>0.2</erp>
          </limit>
          <suspension>
            <cfm>0</cfm>
            <erp>0.2</erp>
          </suspension>
        </ode>
      </physics>
    </joint>
<link name = "link_4" >
<pose>0.45	0.0	0.0	0.0	0.0	0.0	</pose>

      <inertial>
        <pose>0 0 0 0 -0 0</pose>
        <mass>0.001</mass>
        <inertia>
          <ixx>0.0001</ixx>
          <ixy>0.0</ixy>
          <ixz>0.0</ixz>
          <iyy>0.0001</iyy>
          <iyz>0.0</iyz>
          <izz>0.0001</izz>
        </inertia>
      </inertial>
      <visual name='link_4_vis'>
        <pose>0 0 0 0.0 1.57079 0</pose>
        <geometry>
          <cylinder>
            <length>0.1</length>
            <radius>0.00125</radius>
          </cylinder>
        </geometry>
        <material>
          <shader type='pixel'/>
          <script>
            <uri>file://media/materials/scripts/gazebo.material</uri>
            <name>Gazebo/Yellow</name>
          </script>
        </material>
        <transparency>0</transparency>
        <cast_shadows>1</cast_shadows>
      </visual>
      <collision name='link_4_collision'>
        <laser_retro>0</laser_retro>
        <max_contacts>10</max_contacts>
        <pose>0  0 0 0.0 1.57079 0</pose>
        <geometry>
          <cylinder>
            <length>0.1</length>
            <radius>0.00125</radius>
          </cylinder>
        </geometry>
      </collision>
    </link>
<joint name='joint_3' type='universal'>
<parent>link_3</parent>
<child>link_4</child>
<pose>-0.05	0.0	0.0	0.0	0.0	0.0	</pose>
<axis>
        <xyz>0 1 0</xyz>
        <dynamics>
          <spring_reference>0</spring_reference>
          <spring_stiffness>0</spring_stiffness>
          <damping>0.0001</damping>
          <friction>0</friction>
        </dynamics>
      </axis>
      <axis2>
        <xyz>0 0 1</xyz>
        <dynamics>
          <spring_reference>0</spring_reference>
          <spring_stiffness>0</spring_stiffness>
          <damping>0.0001</damping>
          <friction>0</friction>
        </dynamics>
      </axis2>
      <physics>
        <ode>
          <limit>
            <cfm>0</cfm>
            <erp>0.2</erp>
          </limit>
          <suspension>
            <cfm>0</cfm>
            <erp>0.2</erp>
          </suspension>
        </ode>
      </physics>
    </joint>
<link name = "link_5" >
<pose>0.55	0.0	0.0	0.0	0.0	0.0	</pose>

      <inertial>
        <pose>0 0 0 0 -0 0</pose>
        <mass>0.001</mass>
        <inertia>
          <ixx>0.0001</ixx>
          <ixy>0.0</ixy>
          <ixz>0.0</ixz>
          <iyy>0.0001</iyy>
          <iyz>0.0</iyz>
          <izz>0.0001</izz>
        </inertia>
      </inertial>
      <visual name='link_5_vis'>
        <pose>0 0 0 0.0 1.57079 0</pose>
        <geometry>
          <cylinder>
            <length>0.1</length>
            <radius>0.00125</radius>
          </cylinder>
        </geometry>
        <material>
          <shader type='pixel'/>
          <script>
            <uri>file://media/materials/scripts/gazebo.material</uri>
            <name>Gazebo/Yellow</name>
          </script>
        </material>
        <transparency>0</transparency>
        <cast_shadows>1</cast_shadows>
      </visual>
      <collision name='link_5_collision'>
        <laser_retro>0</laser_retro>
        <max_contacts>10</max_contacts>
        <pose>0  0 0 0.0 1.57079 0</pose>
        <geometry>
          <cylinder>
            <length>0.1</length>
            <radius>0.00125</radius>
          </cylinder>
        </geometry>
      </collision>
    </link>
<joint name='joint_4' type='universal'>
<parent>link_4</parent>
<child>link_5</child>
<pose>-0.05	0.0	0.0	0.0	0.0	0.0	</pose>
<axis>
        <xyz>0 1 0</xyz>
        <dynamics>
          <spring_reference>0</spring_reference>
          <spring_stiffness>0</spring_stiffness>
          <damping>0.0001</damping>
          <friction>0</friction>
        </dynamics>
      </axis>
      <axis2>
        <xyz>0 0 1</xyz>
        <dynamics>
          <spring_reference>0</spring_reference>
          <spring_stiffness>0</spring_stiffness>
          <damping>0.0001</damping>
          <friction>0</friction>
        </dynamics>
      </axis2>
      <physics>
        <ode>
          <limit>
            <cfm>0</cfm>
            <erp>0.2</erp>
          </limit>
          <suspension>
            <cfm>0</cfm>
            <erp>0.2</erp>
          </suspension>
        </ode>
      </physics>
    </joint>
<link name = "link_6" >
<pose>0.6500000000000001	0.0	0.0	0.0	0.0	0.0	</pose>

      <inertial>
        <pose>0 0 0 0 -0 0</pose>
        <mass>0.001</mass>
        <inertia>
          <ixx>0.0001</ixx>
          <ixy>0.0</ixy>
          <ixz>0.0</ixz>
          <iyy>0.0001</iyy>
          <iyz>0.0</iyz>
          <izz>0.0001</izz>
        </inertia>
      </inertial>
      <visual name='link_6_vis'>
        <pose>0 0 0 0.0 1.57079 0</pose>
        <geometry>
          <cylinder>
            <length>0.1</length>
            <radius>0.00125</radius>
          </cylinder>
        </geometry>
        <material>
          <shader type='pixel'/>
          <script>
            <uri>file://media/materials/scripts/gazebo.material</uri>
            <name>Gazebo/Yellow</name>
          </script>
        </material>
        <transparency>0</transparency>
        <cast_shadows>1</cast_shadows>
      </visual>
      <collision name='link_6_collision'>
        <laser_retro>0</laser_retro>
        <max_contacts>10</max_contacts>
        <pose>0  0 0 0.0 1.57079 0</pose>
        <geometry>
          <cylinder>
            <length>0.1</length>
            <radius>0.00125</radius>
          </cylinder>
        </geometry>
      </collision>
    </link>
<joint name='joint_5' type='universal'>
<parent>link_5</parent>
<child>link_6</child>
<pose>-0.05	0.0	0.0	0.0	0.0	0.0	</pose>
<axis>
        <xyz>0 1 0</xyz>
        <dynamics>
          <spring_reference>0</spring_reference>
          <spring_stiffness>0</spring_stiffness>
          <damping>0.0001</damping>
          <friction>0</friction>
        </dynamics>
      </axis>
      <axis2>
        <xyz>0 0 1</xyz>
        <dynamics>
          <spring_reference>0</spring_reference>
          <spring_stiffness>0</spring_stiffness>
          <damping>0.0001</damping>
          <friction>0</friction>
        </dynamics>
      </axis2>
      <physics>
        <ode>
          <limit>
            <cfm>0</cfm>
            <erp>0.2</erp>
          </limit>
          <suspension>
            <cfm>0</cfm>
            <erp>0.2</erp>
          </suspension>
        </ode>
      </physics>
    </joint>
<link name = "link_7" >
<pose>0.7500000000000001	0.0	0.0	0.0	0.0	0.0	</pose>

      <inertial>
        <pose>0 0 0 0 -0 0</pose>
        <mass>0.001</mass>
        <inertia>
          <ixx>0.0001</ixx>
          <ixy>0.0</ixy>
          <ixz>0.0</ixz>
          <iyy>0.0001</iyy>
          <iyz>0.0</iyz>
          <izz>0.0001</izz>
        </inertia>
      </inertial>
      <visual name='link_7_vis'>
        <pose>0 0 0 0.0 1.57079 0</pose>
        <geometry>
          <cylinder>
            <length>0.1</length>
            <radius>0.00125</radius>
          </cylinder>
        </geometry>
        <material>
          <shader type='pixel'/>
          <script>
            <uri>file://media/materials/scripts/gazebo.material</uri>
            <name>Gazebo/Yellow</name>
          </script>
        </material>
        <transparency>0</transparency>
        <cast_shadows>1</cast_shadows>
      </visual>
      <collision name='link_7_collision'>
        <laser_retro>0</laser_retro>
        <max_contacts>10</max_contacts>
        <pose>0  0 0 0.0 1.57079 0</pose>
        <geometry>
          <cylinder>
            <length>0.1</length>
            <radius>0.00125</radius>
          </cylinder>
        </geometry>
      </collision>
    </link>
<joint name='joint_6' type='universal'>
<parent>link_6</parent>
<child>link_7</child>
<pose>-0.05	0.0	0.0	0.0	0.0	0.0	</pose>
<axis>
        <xyz>0 1 0</xyz>
        <dynamics>
          <spring_reference>0</spring_reference>
          <spring_stiffness>0</spring_stiffness>
          <damping>0.0001</damping>
          <friction>0</friction>
        </dynamics>
      </axis>
      <axis2>
        <xyz>0 0 1</xyz>
        <dynamics>
          <spring_reference>0</spring_reference>
          <spring_stiffness>0</spring_stiffness>
          <damping>0.0001</damping>
          <friction>0</friction>
        </dynamics>
      </axis2>
      <physics>
        <ode>
          <limit>
            <cfm>0</cfm>
            <erp>0.2</erp>
          </limit>
          <suspension>
            <cfm>0</cfm>
            <erp>0.2</erp>
          </suspension>
        </ode>
      </physics>
    </joint>
<link name = "link_8" >
<pose>0.8500000000000001	0.0	0.0	0.0	0.0	0.0	</pose>

      <inertial>
        <pose>0 0 0 0 -0 0</pose>
        <mass>0.001</mass>
        <inertia>
          <ixx>0.0001</ixx>
          <ixy>0.0</ixy>
          <ixz>0.0</ixz>
          <iyy>0.0001</iyy>
          <iyz>0.0</iyz>
          <izz>0.0001</izz>
        </inertia>
      </inertial>
      <visual name='link_8_vis'>
        <pose>0 0 0 0.0 1.57079 0</pose>
        <geometry>
          <cylinder>
            <length>0.1</length>
            <radius>0.00125</radius>
          </cylinder>
        </geometry>
        <material>
          <shader type='pixel'/>
          <script>
            <uri>file://media/materials/scripts/gazebo.material</uri>
            <name>Gazebo/Yellow</name>
          </script>
        </material>
        <transparency>0</transparency>
        <cast_shadows>1</cast_shadows>
      </visual>
      <collision name='link_8_collision'>
        <laser_retro>0</laser_retro>
        <max_contacts>10</max_contacts>
        <pose>0  0 0 0.0 1.57079 0</pose>
        <geometry>
          <cylinder>
            <length>0.1</length>
            <radius>0.00125</radius>
          </cylinder>
        </geometry>
      </collision>
    </link>
<joint name='joint_7' type='universal'>
<parent>link_7</parent>
<child>link_8</child>
<pose>-0.05	0.0	0.0	0.0	0.0	0.0	</pose>
<axis>
        <xyz>0 1 0</xyz>
        <dynamics>
          <spring_reference>0</spring_reference>
          <spring_stiffness>0</spring_stiffness>
          <damping>0.0001</damping>
          <friction>0</friction>
        </dynamics>
      </axis>
      <axis2>
        <xyz>0 0 1</xyz>
        <dynamics>
          <spring_reference>0</spring_reference>
          <spring_stiffness>0</spring_stiffness>
          <damping>0.0001</damping>
          <friction>0</friction>
        </dynamics>
      </axis2>
      <physics>
        <ode>
          <limit>
            <cfm>0</cfm>
            <erp>0.2</erp>
          </limit>
          <suspension>
            <cfm>0</cfm>
            <erp>0.2</erp>
          </suspension>
        </ode>
      </physics>
    </joint>
<link name = "link_9" >
<pose>0.9500000000000001	0.0	0.0	0.0	0.0	0.0	</pose>

      <inertial>
        <pose>0 0 0 0 -0 0</pose>
        <mass>0.001</mass>
        <inertia>
          <ixx>0.0001</ixx>
          <ixy>0.0</ixy>
          <ixz>0.0</ixz>
          <iyy>0.0001</iyy>
          <iyz>0.0</iyz>
          <izz>0.0001</izz>
        </inertia>
      </inertial>
      <visual name='link_9_vis'>
        <pose>0 0 0 0.0 1.57079 0</pose>
        <geometry>
          <cylinder>
            <length>0.1</length>
            <radius>0.00125</radius>
          </cylinder>
        </geometry>
        <material>
          <shader type='pixel'/>
          <script>
            <uri>file://media/materials/scripts/gazebo.material</uri>
            <name>Gazebo/Yellow</name>
          </script>
        </material>
        <transparency>0</transparency>
        <cast_shadows>1</cast_shadows>
      </visual>
      <collision name='link_9_collision'>
        <laser_retro>0</laser_retro>
        <max_contacts>10</max_contacts>
        <pose>0  0 0 0.0 1.57079 0</pose>
        <geometry>
          <cylinder>
            <length>0.1</length>
            <radius>0.00125</radius>
          </cylinder>
        </geometry>
      </collision>
    </link>
<joint name='joint_8' type='universal'>
<parent>link_8</parent>
<child>link_9</child>
<pose>-0.05	0.0	0.0	0.0	0.0	0.0	</pose>
<axis>
        <xyz>0 1 0</xyz>
        <dynamics>
          <spring_reference>0</spring_reference>
          <spring_stiffness>0</spring_stiffness>
          <damping>0.0001</damping>
          <friction>0</friction>
        </dynamics>
      </axis>
      <axis2>
        <xyz>0 0 1</xyz>
        <dynamics>
          <spring_reference>0</spring_reference>
          <spring_stiffness>0</spring_stiffness>
          <damping>0.0001</damping>
          <friction>0</friction>
        </dynamics>
      </axis2>
      <physics>
        <ode>
          <limit>
            <cfm>0</cfm>
            <erp>0.2</erp>
          </limit>
          <suspension>
            <cfm>0</cfm>
            <erp>0.2</erp>
          </suspension>
        </ode>
      </physics>
    </joint>
</model>
</sdf>
